[2024-07-12T18:20:15.633+0000] {local_task_job_runner.py:120} INFO - ::group::Pre task execution logs
[2024-07-12T18:20:15.646+0000] {taskinstance.py:2076} INFO - Dependencies all met for dep_context=non-requeueable deps ti=<TaskInstance: init_ods_layer.restore_dump manual__2024-07-12T18:20:04.894781+00:00 [queued]>
[2024-07-12T18:20:15.649+0000] {taskinstance.py:2076} INFO - Dependencies all met for dep_context=requeueable deps ti=<TaskInstance: init_ods_layer.restore_dump manual__2024-07-12T18:20:04.894781+00:00 [queued]>
[2024-07-12T18:20:15.649+0000] {taskinstance.py:2306} INFO - Starting attempt 1 of 1
[2024-07-12T18:20:15.654+0000] {taskinstance.py:2330} INFO - Executing <Task(BashOperator): restore_dump> on 2024-07-12 18:20:04.894781+00:00
[2024-07-12T18:20:15.659+0000] {warnings.py:112} WARNING - /home/***/.local/lib/python3.12/site-packages/***/task/task_runner/standard_task_runner.py:61: DeprecationWarning: This process (pid=10302) is multi-threaded, use of fork() may lead to deadlocks in the child.
  pid = os.fork()

[2024-07-12T18:20:15.660+0000] {standard_task_runner.py:63} INFO - Started process 10304 to run task
[2024-07-12T18:20:15.660+0000] {standard_task_runner.py:90} INFO - Running: ['***', 'tasks', 'run', 'init_ods_layer', 'restore_dump', 'manual__2024-07-12T18:20:04.894781+00:00', '--job-id', '86', '--raw', '--subdir', 'DAGS_FOLDER/init_ods.py', '--cfg-path', '/tmp/tmpuvh5e7ud']
[2024-07-12T18:20:15.661+0000] {standard_task_runner.py:91} INFO - Job 86: Subtask restore_dump
[2024-07-12T18:20:15.684+0000] {task_command.py:426} INFO - Running <TaskInstance: init_ods_layer.restore_dump manual__2024-07-12T18:20:04.894781+00:00 [running]> on host 8047aa21fe02
[2024-07-12T18:20:15.735+0000] {taskinstance.py:2648} INFO - Exporting env vars: AIRFLOW_CTX_DAG_OWNER='***' AIRFLOW_CTX_DAG_ID='init_ods_layer' AIRFLOW_CTX_TASK_ID='restore_dump' AIRFLOW_CTX_EXECUTION_DATE='2024-07-12T18:20:04.894781+00:00' AIRFLOW_CTX_TRY_NUMBER='1' AIRFLOW_CTX_DAG_RUN_ID='manual__2024-07-12T18:20:04.894781+00:00'
[2024-07-12T18:20:15.737+0000] {taskinstance.py:430} INFO - ::endgroup::
[2024-07-12T18:20:15.739+0000] {subprocess.py:63} INFO - Tmp dir root location: /tmp
[2024-07-12T18:20:15.740+0000] {subprocess.py:75} INFO - Running command: ['/usr/bin/bash', '-c', '\n        export PGPASSWORD="(-`2loJV" &&\n        psql -U etl_user_3 -h 10.82.0.4 -d etl_db_3 -f scripts/sql-scripts/ods_migration.sql\n    ']
[2024-07-12T18:20:15.745+0000] {subprocess.py:86} INFO - Output:
[2024-07-12T18:20:15.749+0000] {subprocess.py:93} INFO - /usr/bin/bash: -c: line 2: unexpected EOF while looking for matching ``'
[2024-07-12T18:20:15.749+0000] {subprocess.py:97} INFO - Command exited with return code 2
[2024-07-12T18:20:15.750+0000] {taskinstance.py:441} INFO - ::group::Post task execution logs
[2024-07-12T18:20:15.754+0000] {taskinstance.py:2905} ERROR - Task failed with exception
Traceback (most recent call last):
  File "/home/airflow/.local/lib/python3.12/site-packages/airflow/models/taskinstance.py", line 465, in _execute_task
    result = _execute_callable(context=context, **execute_callable_kwargs)
             ^^^^^^^^^^^^^^^^^^^^^^^^^^^^^^^^^^^^^^^^^^^^^^^^^^^^^^^^^^^^^
  File "/home/airflow/.local/lib/python3.12/site-packages/airflow/models/taskinstance.py", line 432, in _execute_callable
    return execute_callable(context=context, **execute_callable_kwargs)
           ^^^^^^^^^^^^^^^^^^^^^^^^^^^^^^^^^^^^^^^^^^^^^^^^^^^^^^^^^^^^
  File "/home/airflow/.local/lib/python3.12/site-packages/airflow/models/baseoperator.py", line 401, in wrapper
    return func(self, *args, **kwargs)
           ^^^^^^^^^^^^^^^^^^^^^^^^^^^
  File "/home/airflow/.local/lib/python3.12/site-packages/airflow/operators/bash.py", line 243, in execute
    raise AirflowException(
airflow.exceptions.AirflowException: Bash command failed. The command returned a non-zero exit code 2.
[2024-07-12T18:20:15.756+0000] {taskinstance.py:1206} INFO - Marking task as FAILED. dag_id=init_ods_layer, task_id=restore_dump, run_id=manual__2024-07-12T18:20:04.894781+00:00, execution_date=20240712T182004, start_date=20240712T182015, end_date=20240712T182015
[2024-07-12T18:20:15.761+0000] {standard_task_runner.py:110} ERROR - Failed to execute job 86 for task restore_dump (Bash command failed. The command returned a non-zero exit code 2.; 10304)
[2024-07-12T18:20:15.805+0000] {local_task_job_runner.py:240} INFO - Task exited with return code 1
[2024-07-12T18:20:15.817+0000] {taskinstance.py:3503} INFO - 0 downstream tasks scheduled from follow-on schedule check
[2024-07-12T18:20:15.819+0000] {local_task_job_runner.py:222} INFO - ::endgroup::
