[2024-07-20T20:42:18.467+0000] {local_task_job_runner.py:120} INFO - ::group::Pre task execution logs
[2024-07-20T20:42:18.481+0000] {taskinstance.py:2076} INFO - Dependencies all met for dep_context=non-requeueable deps ti=<TaskInstance: refresh_ods.restore_dump manual__2024-07-20T20:42:08.758482+00:00 [queued]>
[2024-07-20T20:42:18.486+0000] {taskinstance.py:2076} INFO - Dependencies all met for dep_context=requeueable deps ti=<TaskInstance: refresh_ods.restore_dump manual__2024-07-20T20:42:08.758482+00:00 [queued]>
[2024-07-20T20:42:18.486+0000] {taskinstance.py:2306} INFO - Starting attempt 1 of 2
[2024-07-20T20:42:18.492+0000] {taskinstance.py:2330} INFO - Executing <Task(BashOperator): restore_dump> on 2024-07-20 20:42:08.758482+00:00
[2024-07-20T20:42:18.504+0000] {warnings.py:112} WARNING - /home/***/.local/lib/python3.12/site-packages/***/task/task_runner/standard_task_runner.py:61: DeprecationWarning: This process (pid=2719) is multi-threaded, use of fork() may lead to deadlocks in the child.
  pid = os.fork()

[2024-07-20T20:42:18.506+0000] {standard_task_runner.py:63} INFO - Started process 2721 to run task
[2024-07-20T20:42:18.505+0000] {standard_task_runner.py:90} INFO - Running: ['***', 'tasks', 'run', 'refresh_ods', 'restore_dump', 'manual__2024-07-20T20:42:08.758482+00:00', '--job-id', '231', '--raw', '--subdir', 'DAGS_FOLDER/refresh_ods.py', '--cfg-path', '/tmp/tmpy8ua0h12']
[2024-07-20T20:42:18.507+0000] {standard_task_runner.py:91} INFO - Job 231: Subtask restore_dump
[2024-07-20T20:42:18.535+0000] {task_command.py:426} INFO - Running <TaskInstance: refresh_ods.restore_dump manual__2024-07-20T20:42:08.758482+00:00 [running]> on host 89202c950a25
[2024-07-20T20:42:18.578+0000] {taskinstance.py:2648} INFO - Exporting env vars: AIRFLOW_CTX_DAG_OWNER='***' AIRFLOW_CTX_DAG_ID='refresh_ods' AIRFLOW_CTX_TASK_ID='restore_dump' AIRFLOW_CTX_EXECUTION_DATE='2024-07-20T20:42:08.758482+00:00' AIRFLOW_CTX_TRY_NUMBER='1' AIRFLOW_CTX_DAG_RUN_ID='manual__2024-07-20T20:42:08.758482+00:00'
[2024-07-20T20:42:18.580+0000] {taskinstance.py:430} INFO - ::endgroup::
[2024-07-20T20:42:18.591+0000] {subprocess.py:63} INFO - Tmp dir root location: /tmp
[2024-07-20T20:42:18.592+0000] {subprocess.py:75} INFO - Running command: ['/usr/bin/bash', '-c', "PGPASSWORD='***' pg_restore -h 10.82.0.4 -U etl_user_3 -d etl_db_3 -v -n ods_data /opt/***/dags/scripts/sql-scripts/ods_refresh.sql"]
[2024-07-20T20:42:18.598+0000] {subprocess.py:86} INFO - Output:
[2024-07-20T20:42:18.660+0000] {subprocess.py:93} INFO - pg_restore: error: input file appears to be a text format dump. Please use psql.
[2024-07-20T20:42:18.682+0000] {subprocess.py:97} INFO - Command exited with return code 1
[2024-07-20T20:42:18.693+0000] {taskinstance.py:441} INFO - ::group::Post task execution logs
[2024-07-20T20:42:18.719+0000] {taskinstance.py:2905} ERROR - Task failed with exception
Traceback (most recent call last):
  File "/home/airflow/.local/lib/python3.12/site-packages/airflow/models/taskinstance.py", line 465, in _execute_task
    result = _execute_callable(context=context, **execute_callable_kwargs)
             ^^^^^^^^^^^^^^^^^^^^^^^^^^^^^^^^^^^^^^^^^^^^^^^^^^^^^^^^^^^^^
  File "/home/airflow/.local/lib/python3.12/site-packages/airflow/models/taskinstance.py", line 432, in _execute_callable
    return execute_callable(context=context, **execute_callable_kwargs)
           ^^^^^^^^^^^^^^^^^^^^^^^^^^^^^^^^^^^^^^^^^^^^^^^^^^^^^^^^^^^^
  File "/home/airflow/.local/lib/python3.12/site-packages/airflow/models/baseoperator.py", line 401, in wrapper
    return func(self, *args, **kwargs)
           ^^^^^^^^^^^^^^^^^^^^^^^^^^^
  File "/home/airflow/.local/lib/python3.12/site-packages/airflow/operators/bash.py", line 243, in execute
    raise AirflowException(
airflow.exceptions.AirflowException: Bash command failed. The command returned a non-zero exit code 1.
[2024-07-20T20:42:18.725+0000] {taskinstance.py:1206} INFO - Marking task as UP_FOR_RETRY. dag_id=refresh_ods, task_id=restore_dump, run_id=manual__2024-07-20T20:42:08.758482+00:00, execution_date=20240720T204208, start_date=20240720T204218, end_date=20240720T204218
[2024-07-20T20:42:18.735+0000] {standard_task_runner.py:110} ERROR - Failed to execute job 231 for task restore_dump (Bash command failed. The command returned a non-zero exit code 1.; 2721)
[2024-07-20T20:42:18.774+0000] {local_task_job_runner.py:240} INFO - Task exited with return code 1
[2024-07-20T20:42:18.795+0000] {taskinstance.py:3503} INFO - 0 downstream tasks scheduled from follow-on schedule check
[2024-07-20T20:42:18.796+0000] {local_task_job_runner.py:222} INFO - ::endgroup::
