[2024-07-20T21:49:30.650+0000] {local_task_job_runner.py:120} INFO - ::group::Pre task execution logs
[2024-07-20T21:49:30.681+0000] {taskinstance.py:2076} INFO - Dependencies all met for dep_context=non-requeueable deps ti=<TaskInstance: refresh_ods.restore_dump manual__2024-07-20T21:49:08.576593+00:00 [queued]>
[2024-07-20T21:49:30.687+0000] {taskinstance.py:2076} INFO - Dependencies all met for dep_context=requeueable deps ti=<TaskInstance: refresh_ods.restore_dump manual__2024-07-20T21:49:08.576593+00:00 [queued]>
[2024-07-20T21:49:30.688+0000] {taskinstance.py:2306} INFO - Starting attempt 1 of 2
[2024-07-20T21:49:30.697+0000] {taskinstance.py:2330} INFO - Executing <Task(BashOperator): restore_dump> on 2024-07-20 21:49:08.576593+00:00
[2024-07-20T21:49:30.752+0000] {warnings.py:112} WARNING - /home/***/.local/lib/python3.12/site-packages/***/task/task_runner/standard_task_runner.py:61: DeprecationWarning: This process (pid=3515) is multi-threaded, use of fork() may lead to deadlocks in the child.
  pid = os.fork()

[2024-07-20T21:49:30.753+0000] {standard_task_runner.py:90} INFO - Running: ['***', 'tasks', 'run', 'refresh_ods', 'restore_dump', 'manual__2024-07-20T21:49:08.576593+00:00', '--job-id', '280', '--raw', '--subdir', 'DAGS_FOLDER/refresh_ods.py', '--cfg-path', '/tmp/tmp5edc1th8']
[2024-07-20T21:49:30.756+0000] {standard_task_runner.py:63} INFO - Started process 3520 to run task
[2024-07-20T21:49:30.756+0000] {standard_task_runner.py:91} INFO - Job 280: Subtask restore_dump
[2024-07-20T21:49:30.813+0000] {task_command.py:426} INFO - Running <TaskInstance: refresh_ods.restore_dump manual__2024-07-20T21:49:08.576593+00:00 [running]> on host 89202c950a25
[2024-07-20T21:49:31.001+0000] {taskinstance.py:2648} INFO - Exporting env vars: AIRFLOW_CTX_DAG_OWNER='***' AIRFLOW_CTX_DAG_ID='refresh_ods' AIRFLOW_CTX_TASK_ID='restore_dump' AIRFLOW_CTX_EXECUTION_DATE='2024-07-20T21:49:08.576593+00:00' AIRFLOW_CTX_TRY_NUMBER='1' AIRFLOW_CTX_DAG_RUN_ID='manual__2024-07-20T21:49:08.576593+00:00'
[2024-07-20T21:49:31.008+0000] {taskinstance.py:430} INFO - ::endgroup::
[2024-07-20T21:49:31.011+0000] {subprocess.py:63} INFO - Tmp dir root location: /tmp
[2024-07-20T21:49:31.013+0000] {subprocess.py:75} INFO - Running command: ['/usr/bin/bash', '-c', "PGPASSWORD='***' pg_restore -h 10.82.0.4 -U etl_user_3 -d etl_db_3 -v -n ods_data /opt/***/dags/scripts/sql-scripts/ods_refresh.dump"]
[2024-07-20T21:49:31.024+0000] {subprocess.py:86} INFO - Output:
[2024-07-20T21:49:31.090+0000] {subprocess.py:93} INFO - pg_restore: error: input file is too short (read 0, expected 5)
[2024-07-20T21:49:31.095+0000] {subprocess.py:97} INFO - Command exited with return code 1
[2024-07-20T21:49:31.097+0000] {taskinstance.py:441} INFO - ::group::Post task execution logs
[2024-07-20T21:49:31.124+0000] {taskinstance.py:2905} ERROR - Task failed with exception
Traceback (most recent call last):
  File "/home/airflow/.local/lib/python3.12/site-packages/airflow/models/taskinstance.py", line 465, in _execute_task
    result = _execute_callable(context=context, **execute_callable_kwargs)
             ^^^^^^^^^^^^^^^^^^^^^^^^^^^^^^^^^^^^^^^^^^^^^^^^^^^^^^^^^^^^^
  File "/home/airflow/.local/lib/python3.12/site-packages/airflow/models/taskinstance.py", line 432, in _execute_callable
    return execute_callable(context=context, **execute_callable_kwargs)
           ^^^^^^^^^^^^^^^^^^^^^^^^^^^^^^^^^^^^^^^^^^^^^^^^^^^^^^^^^^^^
  File "/home/airflow/.local/lib/python3.12/site-packages/airflow/models/baseoperator.py", line 401, in wrapper
    return func(self, *args, **kwargs)
           ^^^^^^^^^^^^^^^^^^^^^^^^^^^
  File "/home/airflow/.local/lib/python3.12/site-packages/airflow/operators/bash.py", line 243, in execute
    raise AirflowException(
airflow.exceptions.AirflowException: Bash command failed. The command returned a non-zero exit code 1.
[2024-07-20T21:49:31.160+0000] {taskinstance.py:1206} INFO - Marking task as UP_FOR_RETRY. dag_id=refresh_ods, task_id=restore_dump, run_id=manual__2024-07-20T21:49:08.576593+00:00, execution_date=20240720T214908, start_date=20240720T214930, end_date=20240720T214931
[2024-07-20T21:49:31.175+0000] {standard_task_runner.py:110} ERROR - Failed to execute job 280 for task restore_dump (Bash command failed. The command returned a non-zero exit code 1.; 3520)
[2024-07-20T21:49:31.230+0000] {local_task_job_runner.py:240} INFO - Task exited with return code 1
[2024-07-20T21:49:31.299+0000] {local_task_job_runner.py:222} INFO - ::endgroup::
