[2024-07-20T16:53:22.143+0000] {local_task_job_runner.py:120} INFO - ::group::Pre task execution logs
[2024-07-20T16:53:22.161+0000] {taskinstance.py:2076} INFO - Dependencies all met for dep_context=non-requeueable deps ti=<TaskInstance: daily_copy_schema_optimized_with_cache.copy_all_tables manual__2024-07-20T16:53:15.198618+00:00 [queued]>
[2024-07-20T16:53:22.164+0000] {taskinstance.py:2076} INFO - Dependencies all met for dep_context=requeueable deps ti=<TaskInstance: daily_copy_schema_optimized_with_cache.copy_all_tables manual__2024-07-20T16:53:15.198618+00:00 [queued]>
[2024-07-20T16:53:22.164+0000] {taskinstance.py:2306} INFO - Starting attempt 1 of 2
[2024-07-20T16:53:22.169+0000] {taskinstance.py:2330} INFO - Executing <Task(PythonOperator): copy_all_tables> on 2024-07-20 16:53:15.198618+00:00
[2024-07-20T16:53:22.183+0000] {warnings.py:112} WARNING - /home/***/.local/lib/python3.12/site-packages/***/task/task_runner/standard_task_runner.py:61: DeprecationWarning: This process (pid=275) is multi-threaded, use of fork() may lead to deadlocks in the child.
  pid = os.fork()

[2024-07-20T16:53:22.184+0000] {standard_task_runner.py:63} INFO - Started process 277 to run task
[2024-07-20T16:53:22.184+0000] {standard_task_runner.py:90} INFO - Running: ['***', 'tasks', 'run', 'daily_copy_schema_optimized_with_cache', 'copy_all_tables', 'manual__2024-07-20T16:53:15.198618+00:00', '--job-id', '173', '--raw', '--subdir', 'DAGS_FOLDER/update_ods.py', '--cfg-path', '/tmp/tmp6xd4rwxi']
[2024-07-20T16:53:22.185+0000] {standard_task_runner.py:91} INFO - Job 173: Subtask copy_all_tables
[2024-07-20T16:53:22.220+0000] {task_command.py:426} INFO - Running <TaskInstance: daily_copy_schema_optimized_with_cache.copy_all_tables manual__2024-07-20T16:53:15.198618+00:00 [running]> on host 89202c950a25
[2024-07-20T16:53:22.273+0000] {taskinstance.py:2648} INFO - Exporting env vars: AIRFLOW_CTX_DAG_OWNER='***' AIRFLOW_CTX_DAG_ID='daily_copy_schema_optimized_with_cache' AIRFLOW_CTX_TASK_ID='copy_all_tables' AIRFLOW_CTX_EXECUTION_DATE='2024-07-20T16:53:15.198618+00:00' AIRFLOW_CTX_TRY_NUMBER='1' AIRFLOW_CTX_DAG_RUN_ID='manual__2024-07-20T16:53:15.198618+00:00'
[2024-07-20T16:53:22.279+0000] {taskinstance.py:430} INFO - ::endgroup::
[2024-07-20T16:53:22.288+0000] {base.py:84} INFO - Using connection ID 'source_db' for task execution.
[2024-07-20T16:53:22.422+0000] {base.py:84} INFO - Using connection ID 'target_db' for task execution.
[2024-07-20T17:14:21.388+0000] {taskinstance.py:441} INFO - ::group::Post task execution logs
[2024-07-20T17:14:21.456+0000] {taskinstance.py:2905} ERROR - Task failed with exception
Traceback (most recent call last):
  File "/home/airflow/.local/lib/python3.12/site-packages/airflow/models/taskinstance.py", line 465, in _execute_task
    result = _execute_callable(context=context, **execute_callable_kwargs)
             ^^^^^^^^^^^^^^^^^^^^^^^^^^^^^^^^^^^^^^^^^^^^^^^^^^^^^^^^^^^^^
  File "/home/airflow/.local/lib/python3.12/site-packages/airflow/models/taskinstance.py", line 432, in _execute_callable
    return execute_callable(context=context, **execute_callable_kwargs)
           ^^^^^^^^^^^^^^^^^^^^^^^^^^^^^^^^^^^^^^^^^^^^^^^^^^^^^^^^^^^^
  File "/home/airflow/.local/lib/python3.12/site-packages/airflow/models/baseoperator.py", line 401, in wrapper
    return func(self, *args, **kwargs)
           ^^^^^^^^^^^^^^^^^^^^^^^^^^^
  File "/home/airflow/.local/lib/python3.12/site-packages/airflow/operators/python.py", line 235, in execute
    return_value = self.execute_callable()
                   ^^^^^^^^^^^^^^^^^^^^^^^
  File "/home/airflow/.local/lib/python3.12/site-packages/airflow/operators/python.py", line 252, in execute_callable
    return self.python_callable(*self.op_args, **self.op_kwargs)
           ^^^^^^^^^^^^^^^^^^^^^^^^^^^^^^^^^^^^^^^^^^^^^^^^^^^^^
  File "/opt/airflow/dags/update_ods.py", line 74, in copy_all_tables
    target_cursor.executemany(insert_query, rows)
psycopg2.OperationalError: server closed the connection unexpectedly
	This probably means the server terminated abnormally
	before or while processing the request.

[2024-07-20T17:14:21.529+0000] {taskinstance.py:1206} INFO - Marking task as UP_FOR_RETRY. dag_id=daily_copy_schema_optimized_with_cache, task_id=copy_all_tables, run_id=manual__2024-07-20T16:53:15.198618+00:00, execution_date=20240720T165315, start_date=20240720T165322, end_date=20240720T171421
[2024-07-20T17:14:21.563+0000] {standard_task_runner.py:110} ERROR - Failed to execute job 173 for task copy_all_tables (server closed the connection unexpectedly
	This probably means the server terminated abnormally
	before or while processing the request.
; 277)
[2024-07-20T17:14:21.723+0000] {local_task_job_runner.py:240} INFO - Task exited with return code 1
[2024-07-20T17:14:21.788+0000] {taskinstance.py:3503} INFO - 0 downstream tasks scheduled from follow-on schedule check
[2024-07-20T17:14:21.789+0000] {local_task_job_runner.py:222} INFO - ::endgroup::
