[2024-07-20T20:07:21.297+0000] {local_task_job_runner.py:120} INFO - ::group::Pre task execution logs
[2024-07-20T20:07:21.332+0000] {taskinstance.py:2076} INFO - Dependencies all met for dep_context=non-requeueable deps ti=<TaskInstance: refresh_ods.cleanup_target_schema manual__2024-07-20T20:04:50.673399+00:00 [queued]>
[2024-07-20T20:07:21.338+0000] {taskinstance.py:2076} INFO - Dependencies all met for dep_context=requeueable deps ti=<TaskInstance: refresh_ods.cleanup_target_schema manual__2024-07-20T20:04:50.673399+00:00 [queued]>
[2024-07-20T20:07:21.341+0000] {taskinstance.py:2306} INFO - Starting attempt 1 of 2
[2024-07-20T20:07:21.349+0000] {taskinstance.py:2330} INFO - Executing <Task(BashOperator): cleanup_target_schema> on 2024-07-20 20:04:50.673399+00:00
[2024-07-20T20:07:21.359+0000] {warnings.py:112} WARNING - /home/***/.local/lib/python3.12/site-packages/***/task/task_runner/standard_task_runner.py:61: DeprecationWarning: This process (pid=2172) is multi-threaded, use of fork() may lead to deadlocks in the child.
  pid = os.fork()

[2024-07-20T20:07:21.366+0000] {standard_task_runner.py:63} INFO - Started process 2174 to run task
[2024-07-20T20:07:21.367+0000] {standard_task_runner.py:90} INFO - Running: ['***', 'tasks', 'run', 'refresh_ods', 'cleanup_target_schema', 'manual__2024-07-20T20:04:50.673399+00:00', '--job-id', '202', '--raw', '--subdir', 'DAGS_FOLDER/refresh_ods.py', '--cfg-path', '/tmp/tmp3sk8fehn']
[2024-07-20T20:07:21.376+0000] {standard_task_runner.py:91} INFO - Job 202: Subtask cleanup_target_schema
[2024-07-20T20:07:21.440+0000] {task_command.py:426} INFO - Running <TaskInstance: refresh_ods.cleanup_target_schema manual__2024-07-20T20:04:50.673399+00:00 [running]> on host 89202c950a25
[2024-07-20T20:07:21.494+0000] {taskinstance.py:2648} INFO - Exporting env vars: AIRFLOW_CTX_DAG_OWNER='***' AIRFLOW_CTX_DAG_ID='refresh_ods' AIRFLOW_CTX_TASK_ID='cleanup_target_schema' AIRFLOW_CTX_EXECUTION_DATE='2024-07-20T20:04:50.673399+00:00' AIRFLOW_CTX_TRY_NUMBER='1' AIRFLOW_CTX_DAG_RUN_ID='manual__2024-07-20T20:04:50.673399+00:00'
[2024-07-20T20:07:21.499+0000] {taskinstance.py:430} INFO - ::endgroup::
[2024-07-20T20:07:21.505+0000] {subprocess.py:63} INFO - Tmp dir root location: /tmp
[2024-07-20T20:07:21.507+0000] {subprocess.py:75} INFO - Running command: ['/usr/bin/bash', '-c', 'PGPASSWORD=*** psql -h 10.82.0.4 -U etl_user_3 -d etl_db_3 -c "\n        DO $$ DECLARE\n            r RECORD;\n        BEGIN\n            FOR r IN (SELECT tablename FROM pg_tables WHERE schemaname = \'ods_data\') LOOP\n                EXECUTE \'DROP TABLE ods_data.\' || quote_ident(r.tablename) || \' CASCADE\';\n            END LOOP;\n        END $$;"']
[2024-07-20T20:07:21.520+0000] {subprocess.py:86} INFO - Output:
[2024-07-20T20:07:21.541+0000] {subprocess.py:93} INFO - /usr/bin/bash: -c: line 1: unexpected EOF while looking for matching ``'
[2024-07-20T20:07:21.542+0000] {subprocess.py:97} INFO - Command exited with return code 2
[2024-07-20T20:07:21.542+0000] {taskinstance.py:441} INFO - ::group::Post task execution logs
[2024-07-20T20:07:21.550+0000] {taskinstance.py:2905} ERROR - Task failed with exception
Traceback (most recent call last):
  File "/home/airflow/.local/lib/python3.12/site-packages/airflow/models/taskinstance.py", line 465, in _execute_task
    result = _execute_callable(context=context, **execute_callable_kwargs)
             ^^^^^^^^^^^^^^^^^^^^^^^^^^^^^^^^^^^^^^^^^^^^^^^^^^^^^^^^^^^^^
  File "/home/airflow/.local/lib/python3.12/site-packages/airflow/models/taskinstance.py", line 432, in _execute_callable
    return execute_callable(context=context, **execute_callable_kwargs)
           ^^^^^^^^^^^^^^^^^^^^^^^^^^^^^^^^^^^^^^^^^^^^^^^^^^^^^^^^^^^^
  File "/home/airflow/.local/lib/python3.12/site-packages/airflow/models/baseoperator.py", line 401, in wrapper
    return func(self, *args, **kwargs)
           ^^^^^^^^^^^^^^^^^^^^^^^^^^^
  File "/home/airflow/.local/lib/python3.12/site-packages/airflow/operators/bash.py", line 243, in execute
    raise AirflowException(
airflow.exceptions.AirflowException: Bash command failed. The command returned a non-zero exit code 2.
[2024-07-20T20:07:21.557+0000] {taskinstance.py:1206} INFO - Marking task as UP_FOR_RETRY. dag_id=refresh_ods, task_id=cleanup_target_schema, run_id=manual__2024-07-20T20:04:50.673399+00:00, execution_date=20240720T200450, start_date=20240720T200721, end_date=20240720T200721
[2024-07-20T20:07:21.563+0000] {standard_task_runner.py:110} ERROR - Failed to execute job 202 for task cleanup_target_schema (Bash command failed. The command returned a non-zero exit code 2.; 2174)
[2024-07-20T20:07:21.603+0000] {local_task_job_runner.py:240} INFO - Task exited with return code 1
[2024-07-20T20:07:21.627+0000] {taskinstance.py:3503} INFO - 0 downstream tasks scheduled from follow-on schedule check
[2024-07-20T20:07:21.628+0000] {local_task_job_runner.py:222} INFO - ::endgroup::
