[2024-07-12T18:18:46.667+0000] {local_task_job_runner.py:120} INFO - ::group::Pre task execution logs
[2024-07-12T18:18:46.705+0000] {taskinstance.py:2076} INFO - Dependencies all met for dep_context=non-requeueable deps ti=<TaskInstance: init_ods_layer.get_source_params manual__2024-07-12T18:18:43.236269+00:00 [queued]>
[2024-07-12T18:18:46.775+0000] {taskinstance.py:2076} INFO - Dependencies all met for dep_context=requeueable deps ti=<TaskInstance: init_ods_layer.get_source_params manual__2024-07-12T18:18:43.236269+00:00 [queued]>
[2024-07-12T18:18:46.776+0000] {taskinstance.py:2306} INFO - Starting attempt 1 of 1
[2024-07-12T18:18:46.786+0000] {taskinstance.py:2330} INFO - Executing <Task(PythonOperator): get_source_params> on 2024-07-12 18:18:43.236269+00:00
[2024-07-12T18:18:46.828+0000] {warnings.py:112} WARNING - /home/***/.local/lib/python3.12/site-packages/***/task/task_runner/standard_task_runner.py:61: DeprecationWarning: This process (pid=10265) is multi-threaded, use of fork() may lead to deadlocks in the child.
  pid = os.fork()

[2024-07-12T18:18:46.830+0000] {standard_task_runner.py:63} INFO - Started process 10267 to run task
[2024-07-12T18:18:46.831+0000] {standard_task_runner.py:90} INFO - Running: ['***', 'tasks', 'run', 'init_ods_layer', 'get_source_params', 'manual__2024-07-12T18:18:43.236269+00:00', '--job-id', '81', '--raw', '--subdir', 'DAGS_FOLDER/init_ods.py', '--cfg-path', '/tmp/tmp9hqypobj']
[2024-07-12T18:18:46.835+0000] {standard_task_runner.py:91} INFO - Job 81: Subtask get_source_params
[2024-07-12T18:18:46.891+0000] {task_command.py:426} INFO - Running <TaskInstance: init_ods_layer.get_source_params manual__2024-07-12T18:18:43.236269+00:00 [running]> on host 8047aa21fe02
[2024-07-12T18:18:46.941+0000] {taskinstance.py:2648} INFO - Exporting env vars: AIRFLOW_CTX_DAG_OWNER='***' AIRFLOW_CTX_DAG_ID='init_ods_layer' AIRFLOW_CTX_TASK_ID='get_source_params' AIRFLOW_CTX_EXECUTION_DATE='2024-07-12T18:18:43.236269+00:00' AIRFLOW_CTX_TRY_NUMBER='1' AIRFLOW_CTX_DAG_RUN_ID='manual__2024-07-12T18:18:43.236269+00:00'
[2024-07-12T18:18:46.943+0000] {taskinstance.py:430} INFO - ::endgroup::
[2024-07-12T18:18:46.948+0000] {base.py:84} INFO - Using connection ID 'source_db' for task execution.
[2024-07-12T18:20:01.956+0000] {taskinstance.py:441} INFO - ::group::Post task execution logs
[2024-07-12T18:20:01.969+0000] {taskinstance.py:2905} ERROR - Task failed with exception
Traceback (most recent call last):
  File "/home/airflow/.local/lib/python3.12/site-packages/airflow/models/taskinstance.py", line 465, in _execute_task
    result = _execute_callable(context=context, **execute_callable_kwargs)
             ^^^^^^^^^^^^^^^^^^^^^^^^^^^^^^^^^^^^^^^^^^^^^^^^^^^^^^^^^^^^^
  File "/home/airflow/.local/lib/python3.12/site-packages/airflow/models/taskinstance.py", line 432, in _execute_callable
    return execute_callable(context=context, **execute_callable_kwargs)
           ^^^^^^^^^^^^^^^^^^^^^^^^^^^^^^^^^^^^^^^^^^^^^^^^^^^^^^^^^^^^
  File "/home/airflow/.local/lib/python3.12/site-packages/airflow/models/baseoperator.py", line 401, in wrapper
    return func(self, *args, **kwargs)
           ^^^^^^^^^^^^^^^^^^^^^^^^^^^
  File "/home/airflow/.local/lib/python3.12/site-packages/airflow/operators/python.py", line 235, in execute
    return_value = self.execute_callable()
                   ^^^^^^^^^^^^^^^^^^^^^^^
  File "/home/airflow/.local/lib/python3.12/site-packages/airflow/operators/python.py", line 252, in execute_callable
    return self.python_callable(*self.op_args, **self.op_kwargs)
           ^^^^^^^^^^^^^^^^^^^^^^^^^^^^^^^^^^^^^^^^^^^^^^^^^^^^^
  File "/opt/airflow/dags/init_ods.py", line 50, in get_connection_params
    connection = hook.get_conn()
                 ^^^^^^^^^^^^^^^
  File "/home/airflow/.local/lib/python3.12/site-packages/airflow/providers/postgres/hooks/postgres.py", line 175, in get_conn
    self.conn = psycopg2.connect(**conn_args)
                ^^^^^^^^^^^^^^^^^^^^^^^^^^^^^
  File "/home/airflow/.local/lib/python3.12/site-packages/psycopg2/__init__.py", line 122, in connect
    conn = _connect(dsn, connection_factory=connection_factory, **kwasync)
           ^^^^^^^^^^^^^^^^^^^^^^^^^^^^^^^^^^^^^^^^^^^^^^^^^^^^^^^^^^^^^^^
psycopg2.OperationalError: connection to server at "10.82.0.4", port 5432 failed: Connection refused
	Is the server running on that host and accepting TCP/IP connections?

[2024-07-12T18:20:02.081+0000] {taskinstance.py:1206} INFO - Marking task as FAILED. dag_id=init_ods_layer, task_id=get_source_params, run_id=manual__2024-07-12T18:18:43.236269+00:00, execution_date=20240712T181843, start_date=20240712T181846, end_date=20240712T182002
[2024-07-12T18:20:02.113+0000] {standard_task_runner.py:110} ERROR - Failed to execute job 81 for task get_source_params (connection to server at "10.82.0.4", port 5432 failed: Connection refused
	Is the server running on that host and accepting TCP/IP connections?
; 10267)
[2024-07-12T18:20:02.160+0000] {local_task_job_runner.py:240} INFO - Task exited with return code 1
[2024-07-12T18:20:02.195+0000] {taskinstance.py:3503} INFO - 0 downstream tasks scheduled from follow-on schedule check
[2024-07-12T18:20:02.198+0000] {local_task_job_runner.py:222} INFO - ::endgroup::
