[2024-07-10T14:28:34.213+0000] {local_task_job_runner.py:120} INFO - ::group::Pre task execution logs
[2024-07-10T14:28:34.223+0000] {taskinstance.py:2076} INFO - Dependencies all met for dep_context=non-requeueable deps ti=<TaskInstance: test_postgres.insert_step scheduled__2024-07-09T00:00:00+00:00 [queued]>
[2024-07-10T14:28:34.226+0000] {taskinstance.py:2076} INFO - Dependencies all met for dep_context=requeueable deps ti=<TaskInstance: test_postgres.insert_step scheduled__2024-07-09T00:00:00+00:00 [queued]>
[2024-07-10T14:28:34.226+0000] {taskinstance.py:2306} INFO - Starting attempt 1 of 1
[2024-07-10T14:28:34.231+0000] {taskinstance.py:2330} INFO - Executing <Task(PostgresOperator): insert_step> on 2024-07-09 00:00:00+00:00
[2024-07-10T14:28:34.244+0000] {warnings.py:112} WARNING - /home/***/.local/lib/python3.12/site-packages/***/task/task_runner/standard_task_runner.py:61: DeprecationWarning: This process (pid=47) is multi-threaded, use of fork() may lead to deadlocks in the child.
  pid = os.fork()

[2024-07-10T14:28:34.245+0000] {standard_task_runner.py:63} INFO - Started process 49 to run task
[2024-07-10T14:28:34.245+0000] {standard_task_runner.py:90} INFO - Running: ['***', 'tasks', 'run', 'test_postgres', 'insert_step', 'scheduled__2024-07-09T00:00:00+00:00', '--job-id', '21', '--raw', '--subdir', 'DAGS_FOLDER/test_db_dag.py', '--cfg-path', '/tmp/tmp3iqmd45n']
[2024-07-10T14:28:34.247+0000] {standard_task_runner.py:91} INFO - Job 21: Subtask insert_step
[2024-07-10T14:28:34.266+0000] {task_command.py:426} INFO - Running <TaskInstance: test_postgres.insert_step scheduled__2024-07-09T00:00:00+00:00 [running]> on host 9c639793bd4a
[2024-07-10T14:28:34.316+0000] {taskinstance.py:2648} INFO - Exporting env vars: AIRFLOW_CTX_DAG_OWNER='***' AIRFLOW_CTX_DAG_ID='test_postgres' AIRFLOW_CTX_TASK_ID='insert_step' AIRFLOW_CTX_EXECUTION_DATE='2024-07-09T00:00:00+00:00' AIRFLOW_CTX_TRY_NUMBER='1' AIRFLOW_CTX_DAG_RUN_ID='scheduled__2024-07-09T00:00:00+00:00'
[2024-07-10T14:28:34.317+0000] {taskinstance.py:430} INFO - ::endgroup::
[2024-07-10T14:28:34.318+0000] {sql.py:276} INFO - Executing: SELECT * FROM source_data.фреймворки_и_уровень_знаний_сотру ORDER BY название
[2024-07-10T14:28:34.325+0000] {base.py:84} INFO - Using connection ID 'source_db' for task execution.
[2024-07-10T14:28:34.337+0000] {base.py:84} INFO - Using connection ID 'source_db' for task execution.
[2024-07-10T14:29:49.376+0000] {taskinstance.py:441} INFO - ::group::Post task execution logs
[2024-07-10T14:29:49.389+0000] {taskinstance.py:2905} ERROR - Task failed with exception
Traceback (most recent call last):
  File "/home/airflow/.local/lib/python3.12/site-packages/airflow/models/taskinstance.py", line 465, in _execute_task
    result = _execute_callable(context=context, **execute_callable_kwargs)
             ^^^^^^^^^^^^^^^^^^^^^^^^^^^^^^^^^^^^^^^^^^^^^^^^^^^^^^^^^^^^^
  File "/home/airflow/.local/lib/python3.12/site-packages/airflow/models/taskinstance.py", line 432, in _execute_callable
    return execute_callable(context=context, **execute_callable_kwargs)
           ^^^^^^^^^^^^^^^^^^^^^^^^^^^^^^^^^^^^^^^^^^^^^^^^^^^^^^^^^^^^
  File "/home/airflow/.local/lib/python3.12/site-packages/airflow/models/baseoperator.py", line 401, in wrapper
    return func(self, *args, **kwargs)
           ^^^^^^^^^^^^^^^^^^^^^^^^^^^
  File "/home/airflow/.local/lib/python3.12/site-packages/airflow/providers/common/sql/operators/sql.py", line 282, in execute
    output = hook.run(
             ^^^^^^^^^
  File "/home/airflow/.local/lib/python3.12/site-packages/airflow/providers/common/sql/hooks/sql.py", line 431, in run
    with self._create_autocommit_connection(autocommit) as conn:
  File "/usr/local/lib/python3.12/contextlib.py", line 137, in __enter__
    return next(self.gen)
           ^^^^^^^^^^^^^^
  File "/home/airflow/.local/lib/python3.12/site-packages/airflow/providers/common/sql/hooks/sql.py", line 551, in _create_autocommit_connection
    with closing(self.get_conn()) as conn:
                 ^^^^^^^^^^^^^^^
  File "/home/airflow/.local/lib/python3.12/site-packages/airflow/providers/postgres/hooks/postgres.py", line 175, in get_conn
    self.conn = psycopg2.connect(**conn_args)
                ^^^^^^^^^^^^^^^^^^^^^^^^^^^^^
  File "/home/airflow/.local/lib/python3.12/site-packages/psycopg2/__init__.py", line 122, in connect
    conn = _connect(dsn, connection_factory=connection_factory, **kwasync)
           ^^^^^^^^^^^^^^^^^^^^^^^^^^^^^^^^^^^^^^^^^^^^^^^^^^^^^^^^^^^^^^^
psycopg2.OperationalError: connection to server at "10.82.0.4", port 5432 failed: Connection refused
	Is the server running on that host and accepting TCP/IP connections?

[2024-07-10T14:29:49.437+0000] {taskinstance.py:1206} INFO - Marking task as FAILED. dag_id=test_postgres, task_id=insert_step, run_id=scheduled__2024-07-09T00:00:00+00:00, execution_date=20240709T000000, start_date=20240710T142834, end_date=20240710T142949
[2024-07-10T14:29:49.461+0000] {standard_task_runner.py:110} ERROR - Failed to execute job 21 for task insert_step (connection to server at "10.82.0.4", port 5432 failed: Connection refused
	Is the server running on that host and accepting TCP/IP connections?
; 49)
[2024-07-10T14:29:49.502+0000] {local_task_job_runner.py:240} INFO - Task exited with return code 1
[2024-07-10T14:29:49.525+0000] {warnings.py:112} WARNING - /home/***/.local/lib/python3.12/site-packages/***/models/baseoperator.py:1297: AirflowProviderDeprecationWarning: Call to deprecated class PostgresOperator. (Please use `***.providers.common.sql.operators.sql.SQLExecuteQueryOperator`.Also, you can provide `hook_params={'schema': <database>}`.)
  result = cls.__new__(cls)

[2024-07-10T14:29:49.537+0000] {taskinstance.py:3503} INFO - 0 downstream tasks scheduled from follow-on schedule check
[2024-07-10T14:29:49.539+0000] {local_task_job_runner.py:222} INFO - ::endgroup::
